<mujoco model="humanoid">

  <statistic extent="2" center="0 0 1"/>

  <option timestep="0.00555"/>

  <default>
    <motor ctrlrange="-1 1" ctrllimited="true"/>
    <default class="body">
      <geom  type="capsule" condim="1" friction="1.0 0.05 0.05" solimp=".9 .99 .003" solref=".015 1" material="self"/>
      <joint type="hinge" damping="0.1" stiffness="5" armature=".007" limited="true" solimplimit="0 .99 .01"/>
      <default class="small_joint">
        <joint damping="5.0" stiffness="10" armature=".006"/>
      </default>
      <default class="big_joint">
        <joint damping="5" stiffness="40" armature=".01"/>
      </default>
      <default class="bigger_stiff_joint">
        <joint damping="5" stiffness="80" armature=".01"/>
      </default>
      <default class="big_stiff_joint">
        <joint damping="5" stiffness="60" armature=".02"/>
      </default>
      <site size=".04" group="3"/>
      <default class="force-torque">
        <site type="box" size=".01 .01 .02" rgba="1 0 0 1" />
      </default>
      <default class="touch">
        <site type="capsule" rgba="0 0 1 .3"/>
      </default>
    </default>
  </default>

  <worldbody>
    <geom name="floor" type="plane" conaffinity="1" size="100 100 .2" material="grid"/>
    <body name="torso" pos="0 0 1.5" childclass="body">
      <light name="top" pos="0 0 2" mode="trackcom"/>
      <camera name="back" pos="-3 0 1" xyaxes="0 -1 0 1 0 2" mode="trackcom"/>
      <camera name="side" pos="0 -3 1" xyaxes="1 0 0 0 1 2" mode="trackcom"/>
      <freejoint name="root"/>
      <site name="root" class="force-torque"/>
      <geom name="torso" fromto="0 -.07 0 0 .07 0" size=".07"/>
      <geom name="upper_waist" fromto="-.01 -.06 -.12 -.01 .06 -.12" size=".06"/>
      <site name="torso" class="touch" type="box" pos="0 0 -.05" size=".075 .14 .13"/>
      <body name="head" pos="0 0 .07">
        <joint name="neck_x" axis="1 0 0" range="-50 50" class="small_joint"/>
        <joint name="neck_y" axis="0 1 0" range="-60 40" class="small_joint"/>
        <joint name="neck_z" axis="0 0 1" range="-45 45" class="small_joint"/>
        <geom name="head" type="sphere" pos="0 0 0.14" size=".09"/>
        <site name="head" class="touch" type="sphere" size=".091"/>
        <camera name="egocentric" pos=".09 0 0" xyaxes="0 -1 0 .1 0 1" fovy="80"/>
      </body>
      <body name="lower_waist" pos="-.01 0 -.260" quat="1.000 0 -.002 0">
        <geom name="lower_waist" fromto="0 -.06 0 0 .06 0" size=".06"/>
        <site name="lower_waist" class="touch" size=".061 .06" zaxis="0 1 0"/>
        <joint name="abdomen_z" pos="0 0 0" axis="0 0 1" range="-50 50"  stiffness="150" damping="10" armature=".05"/>
        <joint name="abdomen_y" pos="0 0 0" axis="0 1 0" range="-60 90"  stiffness="150" damping="10" armature=".05"/>
        <body name="pelvis" pos="0 0 -.165" quat="1.000 0 -.002 0">
        <joint name="abdomen_x" pos="0 0 0" axis="1 0 0" range="-60 60" stiffness="150" damping="10" armature=".05"/>
          <geom name="butt" fromto="-.02 -.07 0 -.02 .07 0" size=".09"/>
          <site name="butt" class="touch" size=".091 .07" pos="-.02 0 0" zaxis="0 1 0"/>
          <body name="right_thigh" pos="0 -.1 -.04">
            <site name="right_hip" class="force-torque"/>
            <joint name="right_hip_x" axis="-1 0 0" range="-15 45"  class="big_joint"/>
            <joint name="right_hip_y" axis="0 1 0" range="-120 45" class="bigger_stiff_joint"/>
            <joint name="right_hip_z" axis="0 0 -1" range="-35 60"  class="big_joint"/>
            <geom name="right_thigh" fromto="0 0 0 0 .01 -.34" size=".06"/>
            <site name="right_thigh" class="touch" pos="0 .005 -.17" size=".061 .17" zaxis="0 -1 34"/>
            <body name="right_shin" pos="0 .01 -.403">
              <site name="right_knee" class="force-torque" pos="0 0 .02"/>
              <joint name="right_knee" pos="0 0 0" axis="0 1 0" range="0 160" class="big_joint"/>
              <geom name="right_shin" fromto="0 0 0 0 0 -.3"  size=".049"/>
              <site name="right_shin" class="touch" pos="0 0 -.15" size=".05 .15"/>
              <body name="right_foot" pos="0 0 -.39">
                <site name="right_ankle" class="force-torque"/>
                <joint name="right_ankle_x" pos="0 0 0" axis="1 0 0" range="-30 30"  class="small_joint"/>
                <joint name="right_ankle_y" pos="0 0 0" axis="0 1 0" range="-55 55"  class="small_joint"/>
                <joint name="right_ankle_z" pos="0 0 0" axis="0 0 1" range="-40 40"  class="small_joint"/>
                <geom name="right_foot" type="box" pos="0.045 0 -0.0225" size="0.0885 0.045 0.0275" />
                <site name="right_right_foot" class="touch" pos=".035 -.03 0" size=".03 .11" zaxis="21 -2 0"/>
                <site name="left_right_foot" class="touch" pos=".035 .01 0" size=".03 .11" zaxis="21 2 0"/>
              </body>
            </body>
          </body>
          <body name="left_thigh" pos="0 .1 -.04">
            <site name="left_hip" class="force-torque"/>
            <joint name="left_hip_x" axis="1 0 0" range="-15 45" class="big_joint"/>
            <joint name="left_hip_y" axis="0 1 0" range="-120 45" class="bigger_stiff_joint"/>
            <joint name="left_hip_z" axis="0 0 1" range="-35 60" class="big_joint"/>
            <geom name="left_thigh" fromto="0 0 0 0 -.01 -.34" size=".06"/>
            <site name="left_thigh" class="touch" pos="0 -.005 -.17" size=".061 .17" zaxis="0 1 34"/>
            <body name="left_shin" pos="0 -.01 -.403">
              <site name="left_knee" class="force-torque" pos="0 0 .02"/>
              <joint name="left_knee" pos="0 0 0" axis="0 1 0" range="0 160" class="big_joint"/>
              <geom name="left_shin" fromto="0 0 0 0 0 -.3"  size=".049"/>
              <site name="left_shin" class="touch"  pos="0 0 -.15" size=".05 .15"/>
              <body name="left_foot" pos="0 0 -.39">
                <site name="left_ankle" class="force-torque"/>
                <joint name="left_ankle_x" pos="0 0 0" axis="1 0 0" range="-30 30" class="small_joint"/>
                <joint name="left_ankle_y" pos="0 0 0" axis="0 1 0" range="-55 55" class="small_joint"/>
                <joint name="left_ankle_z" pos="0 0 0" axis="0 0 1" range="-40 40" class="small_joint"/>
                <geom name="left_foot" type="box" pos="0.045 0 -0.0225" size="0.0885 0.045 0.0275"/>
                <site name="right_left_foot" class="touch" pos=".035 -.01 0" size=".03 .11" zaxis="21 -2 0"/>
                <site name="left_left_foot" class="touch" pos=".035 .03 0" size=".03 .11" zaxis="21 2 0"/>
              </body>
            </body>
          </body>
        </body>
      </body>
      <body name="right_upper_arm" pos="0 -0.20 0.01">
        <joint name="right_shoulder_x" axis="-1 0 0" range="0 160"   damping="1" stiffness="10" armature=".006"/>
        <joint name="right_shoulder_y" axis="0 1 0" range="-160 60"   damping="1" stiffness="10" armature=".006"/>
        <joint name="right_shoulder_z" axis="0 0 -1" range="-90 90"   damping="1" stiffness="10" armature=".006"/>
        <geom name="right_upper_arm" fromto="0 0 0 0 -0.01 -.23" size=".04 .16"/>
        <site name="right_upper_arm" class="touch" pos=".08 -.08 -.08" size=".041 .14" zaxis="1 -1 -1"/>
        <body name="right_lower_arm" pos="0 -0.01 -0.25">
          <joint name="right_elbow" axis="0 1 0" range="-160 0" damping="1" stiffness="10" armature=".006"/>
          <geom name="right_lower_arm" fromto="0 0 -0.01 0 -0.01 -.25" size=".031"/>
          <site name="right_lower_arm" class="touch" pos=".09 .09 .09" size=".032 .14" zaxis="1 1 1"/>
          <body name="right_hand" pos="0 -0.01 -.29">
            <geom name="right_hand" type="sphere" size=".04"/>
            <site name="right_hand" class="touch" type="sphere" size=".041"/>
          </body>
        </body>
      </body>
      <body name="left_upper_arm" pos="0 0.20 0.01">
        <joint name="left_shoulder_x" axis="1 0 0" range="0 160"  damping="1" stiffness="10" armature=".006"/>
        <joint name="left_shoulder_y" axis="0 1 0" range="-160 60" damping="1" stiffness="10" armature=".006"/>
        <joint name="left_shoulder_z" axis="0 0 1" range="-90 90"  damping="1" stiffness="10" armature=".006"/>
        <geom name="left_upper_arm" fromto="0 0 0 0 0.01 -.23" size=".04 .16"/>
        <site name="left_upper_arm" class="touch" pos=".08 .08 -.08" size=".041 .14" zaxis="1 1 -1"/>
        <body name="left_lower_arm" pos="0 0.01 -0.25">
          <joint name="left_elbow" axis="0 1 0" range="-160 0" damping="1" stiffness="10" armature=".006"/>
          <geom name="left_lower_arm" fromto="0 0 -0.01 0 0.01 -.25" size=".031"/>
          <site name="left_lower_arm" class="touch" pos=".09 -.09 .09" size=".032 .14" zaxis="1 -1 1"/>
          <body name="left_hand" pos="0 0.01 -.29">
            <geom name="left_hand" type="sphere" size=".04"/>
            <site name="left_hand" class="touch" type="sphere" size=".041"/>
          </body>
        </body>
      </body>
    </body>
  </worldbody>

  <actuator>
    <motor name='neck_x'          gear='20'   joint='neck_x'/>#0
    <motor name='neck_y'          gear='20'   joint='neck_y'/>#1
    <motor name='neck_z'          gear='20'   joint='neck_z'/>#2
    <motor name='abdomen_z'       gear='67.5' joint='abdomen_z'/>#3
    <motor name='abdomen_y'       gear='67.5' joint='abdomen_y'/>#4
    <motor name='abdomen_x'       gear='67.5' joint='abdomen_x'/>#5
    <motor name='right_hip_x'     gear='45'   joint='right_hip_x'/>#6
    <motor name='right_hip_y'     gear='135'  joint='right_hip_y'/>#7
    <motor name='right_hip_z'     gear='45'   joint='right_hip_z'/>#8
    <motor name='right_knee'      gear='60'   joint='right_knee'/>#9
    <motor name='right_ankle_x'   gear='22.5' joint='right_ankle_x'/>#10
    <motor name='right_ankle_y'   gear='22.5' joint='right_ankle_y'/>#11
    <motor name='right_ankle_z'   gear='22.5' joint='right_ankle_z'/>#12
    <motor name='left_hip_x'      gear='45'   joint='left_hip_x'/>#13
    <motor name='left_hip_y'      gear='135'  joint='left_hip_y'/>#14
    <motor name='left_hip_z'      gear='45'   joint='left_hip_z'/>#15
    <motor name='left_knee'       gear='60'   joint='left_knee'/>#16
    <motor name='left_ankle_x'    gear='22.5' joint='left_ankle_x'/>#17
    <motor name='left_ankle_y'    gear='22.5' joint='left_ankle_y'/>#18
    <motor name='left_ankle_z'    gear='22.5' joint='left_ankle_z'/>#19
    <motor name='right_shoulder_x' gear='45'  joint='right_shoulder_x'/>#20
    <motor name='right_shoulder_y' gear='45'  joint='right_shoulder_y'/>#21
    <motor name='right_shoulder_z' gear='45'  joint='right_shoulder_z'/>#22
    <motor name='right_elbow'     gear='20'   joint='right_elbow'/>#23
    <motor name='left_shoulder_x' gear='45'   joint='left_shoulder_x'/>#24
    <motor name='left_shoulder_y' gear='45'   joint='left_shoulder_y'/>#25
    <motor name='left_shoulder_z' gear='45'   joint='left_shoulder_z'/>#26
    <motor name='left_elbow'      gear='20'   joint='left_elbow'/>#27
  </actuator>

  <sensor>
    <subtreelinvel name="torso_subtreelinvel" body="torso"/>
    <accelerometer name="torso_accel"    site="root"/>
    <velocimeter name="torso_vel"        site="root"/>
    <gyro name="torso_gyro"              site="root"/>

    <force name="left_ankle_force"       site="left_ankle"/>
    <force name="right_ankle_force"      site="right_ankle"/>
    <force name="left_knee_force"        site="left_knee"/>
    <force name="right_knee_force"       site="right_knee"/>
    <force name="left_hip_force"         site="left_hip"/>
    <force name="right_hip_force"        site="right_hip"/>

    <torque name="left_ankle_torque"     site="left_ankle"/>
    <torque name="right_ankle_torque"    site="right_ankle"/>
    <torque name="left_knee_torque"      site="left_knee"/>
    <torque name="right_knee_torque"     site="right_knee"/>
    <torque name="left_hip_torque"       site="left_hip"/>
    <torque name="right_hip_torque"      site="right_hip"/>

    <touch name="torso_touch"            site="torso"/>
    <touch name="head_touch"             site="head"/>
    <touch name="lower_waist_touch"      site="lower_waist"/>
    <touch name="butt_touch"             site="butt"/>
    <touch name="right_thigh_touch"      site="right_thigh"/>
    <touch name="right_shin_touch"       site="right_shin"/>
    <touch name="right_right_foot_touch" site="right_right_foot"/>
    <touch name="left_right_foot_touch"  site="left_right_foot"/>
    <touch name="left_thigh_touch"       site="left_thigh"/>
    <touch name="left_shin_touch"        site="left_shin"/>
    <touch name="right_left_foot_touch"  site="right_left_foot"/>
    <touch name="left_left_foot_touch"   site="left_left_foot"/>
    <touch name="right_upper_arm_touch"  site="right_upper_arm"/>
    <touch name="right_lower_arm_touch"  site="right_lower_arm"/>
    <touch name="right_hand_touch"       site="right_hand"/>
    <touch name="left_upper_arm_touch"   site="left_upper_arm"/>
    <touch name="left_lower_arm_touch"   site="left_lower_arm"/>
    <touch name="left_hand_touch"        site="left_hand"/>
  </sensor>

</mujoco>

